Workbook

Sheet Rules
A1: Detection rules — the VAT Mistakes Rulebook
A2: One row per rule, generated from docs/VAT-Mistakes-Rulebook.md and app/rule_taxonomy.py. 'Source / benchmark' names the statutory anchor only where the rulebook text states one; where it does not, the cell says so rather than inventing a citation. 'In scope' is derived from app/scope.py plus whether the rule needs a data feed the PoC lacks.
A4: # | B4: Rule code | C4: Category (family) | D4: Rule name | E4: Description — what the taxpayer does wrong | F4: Why it happens | G4: How the agent detects it | H4: Source / benchmark — where the rule came from | I4: Data it needs (feed) | J4: Reason code | K4: Reason code meaning | L4: Stage | M4: Rule kind | N4: Severity | O4: Explains a gap? | P4: In scope for this PoC? | Q4: Scope basis | R4: Wired into engine? | S4: Active?
A5: 1 | B5: OUT-01 | C5: Output | D5: Under-declared / omitted standard-rated sales | E5: Reports less standard-rated output than the issued tax invoices show — a slice of 15% sales never reaches `Standard_Rate_Sales`. | F5: Manual re-keying from a sub-ledger that misses branches/POS tills; cash sales left out; deliberate suppression. | G5: Reconstruct expected = Σ `TAXSUBTOTAL.TaxableAmount`/`.TaxAmount` for `INVOICELINE.ItemClassifiedTaxCategoryID='S'` AND `Percent=15`, over `INVOICES` `InvoiceTypeCode IN (388,383)` minus `381`, tax point in period. Compare Σ TaxableAmount vs `Standard_Rate_Sales_Amount_15 (+_Adjustment)` and Σ TaxAmount vs `Standard_Rate_Sales_VAT_Amount_15`. Flag if `reconstructed − declared > τ`. Internal ratio check `VAT_Amount_15 ≈ Amount_15 × 0.15`. | H5: VAT Mistakes Rulebook (docs/VAT-Mistakes-Rulebook.md), family Output — authored for this PoC. No explicit statutory citation recorded in the repo — to be confirmed with a ZATCA SME. | I5: FATOORA e-invoices + declared VAT return boxes (in the PoC data model) | J5: R01 | K5: E-invoice taxable value exceeds the return | L5: materiality | M5: mistake | N5: High | O5: Yes → Standard_Rate_Sales | P5: In scope — not wired | Q5: Reachable from the PoC's data model; no reconciling item written yet. | R5: No | S5: Yes
A6: 2 | B6: OUT-02 | C6: Output | D6: Wrong rate 5% vs 15% (2020-07-01 transition) | E6: Charges/declares 5% on supplies with tax point ≥ 2020-07-01 (should be 15%), or 15% on genuine pre-transition supplies. | F6: ERP tax-code not switched on the rate-change date; long-running contracts; transitional-rule confusion. | G6: For each S-line, tax point = earlier of `IssueDate`/`ActualDeliveryDate`. Flag `Percent=5` where tax point ≥ 2020-07-01 (outside the transitional window) and `=15` where tax point < 2020-07-01. Uplift = Σ affected `TaxableAmount × (0.15−0.05)`. Corroborate: material `Standard_Rate_Sales_Amount_5` for a period wholly post-switch. | H6: VAT Mistakes Rulebook (docs/VAT-Mistakes-Rulebook.md), family Output — authored for this PoC. Statutory anchor stated in the rule: VAT rate change 5% → 15% (2020-07-01). | I6: FATOORA e-invoices + declared VAT return boxes (in the PoC data model) | J6: R07 | K6: Inconsistent tax-category coding | L6: category | M6: mistake | N6: High | O6: Yes → Standard_Rate_Sales _5↔_15 | P6: In scope — not wired | Q6: Reachable from the PoC's data model; no reconciling item written yet. | R6: No | S6: Yes
A7: 3 | B7: OUT-03 | C7: Output | D7: Standard sales mis-declared as zero-rated/exempt | E7: Puts 15% sales into `Zero_Rated_Sales` or `Exempt_Sales`, avoiding output VAT (and, for exempt, distorting input apportionment). | F7: Misreading zero-rating/exemption scope; a Z/E box used as a dumping ground. | G7: Compare declared `Zero_Rated_Sales_Amount` vs reconstructed category-`Z` Σ TaxableAmount, and `Exempt_Sales_Amount` vs category `E`. Flag where declared Z or E **exceeds** invoice-reconstructed Z/E by > τ AND a matching understatement appears in `Standard_Rate_Sales_Amount_15` (paired offset). Confirm the suspect lines carry no `TaxAmount` despite not truly being Z/E. | H7: VAT Mistakes Rulebook (docs/VAT-Mistakes-Rulebook.md), family Output — authored for this PoC. No explicit statutory citation recorded in the repo — to be confirmed with a ZATCA SME. | I7: FATOORA e-invoices + declared VAT return boxes (in the PoC data model) | J7: R07 | K7: Inconsistent tax-category coding | L7: category | M7: mistake | N7: High | O7: Yes → Zero/Exempt ↔ Standard | P7: In scope — not wired | Q7: Reachable from the PoC's data model; no reconciling item written yet. | R7: No | S7: Yes
A8: 4 | B8: OUT-04 | C8: Output | D8: Exports zero-rated without flag / proof | E8: Books sales into `Exports_Amount` at 0% but the invoices are not export-flagged and/or there is no evidence of goods leaving KSA. | F8: Treating any foreign customer as an export; missing customs/transport docs; local supply dressed as export. | G8: Reconcile declared `Exports_Amount` to Σ invoices whose `InvoiceTypeCode` **name** carries the export marker AND category `Z`. Flag the portion with **no** export-flagged invoice, or where `DocumentCurrencyCode='SAR'` with a resident customer (counterparty master). Residual export lacking flag = treated as standard-rated; expected VAT = residual × 15%. | H8: VAT Mistakes Rulebook (docs/VAT-Mistakes-Rulebook.md), family Output — authored for this PoC. No explicit statutory citation recorded in the repo — to be confirmed with a ZATCA SME. | I8: FATOORA e-invoices + declared return boxes; also needs Counterparty BP-master | J8: S02 | K8: Zero-rated supply | L8: category | M8: mistake | N8: High | O8: Partial (reclass Yes; proof customs) | P8: Out of scope | Q8: Needs a feed the PoC does not have: Counterparty BP-master. | R8: No | S8: Yes
A9: 5 | B9: OUT-05 | C9: Output | D9: GCC sales mislabelled | E9: Reports GCC-customer supplies in the wrong box — as exports/zero-rated or in `Sales_To_Customers_GCC` — when the live transitional treatment makes them standard-rated KSA supplies. | F9: Assuming all GCC is export-like; the GCC electronic-services regime not being live means most "GCC sales" are standard-rated local supplies. | G9: Compare `Sales_To_Customers_GCC_Amount` to invoices where **counterparty** nationality is a GCC state. Because intra-GCC defaults to standard KSA VAT, flag GCC-box amounts carrying category `Z`/0% with no export flag; reclass to `Standard_Rate_Sales_Amount_15`, VAT = amount × 15%. Also flag GCC amounts double-counted inside `Exports_Amount`. | H9: VAT Mistakes Rulebook (docs/VAT-Mistakes-Rulebook.md), family Output — authored for this PoC. No explicit statutory citation recorded in the repo — to be confirmed with a ZATCA SME. | I9: FATOORA e-invoices + declared return boxes; also needs Counterparty BP-master; Registration / dereg master | J9: S07 | K9: Non-resident / intra-GCC transaction | L9: category | M9: mistake | N9: Medium | O9: Yes → GCC/Exports ↔ Standard | P9: Out of scope | Q9: Needs a feed the PoC does not have: Counterparty BP-master; Registration / dereg master. | R9: No | S9: Yes
A10: 6 | B10: OUT-06 | C10: Output | D10: Government-supplied sales mishandled (15/5) | E10: Errors in `Government_Supplied_Sales_*_15`/`_5` — omitting government sales, wrong rate split, or netting retentions so the base understates output. | F10: Public-sector contract terms and payment retention; rate-by-tax-point confusion; a separate government billing stream not integrated in VAT prep. | G10: Identify government-customer invoices via **counterparty** master (government BP type) and reconstruct their S-category `TAXSUBTOTAL` by rate. Compare to `Government_Supplied_Sales_Amount_15/_5` and `_VAT_Amount_15/_5`. Flag if reconstructed − declared > τ, or if the 15/5 split contradicts each invoice's tax point vs 2020-07-01 (RATE-TRANSITION). Verify `_VAT_Amount ≈ _Amount × rate`. | H10: VAT Mistakes Rulebook (docs/VAT-Mistakes-Rulebook.md), family Output — authored for this PoC. Statutory anchor stated in the rule: VAT rate change 5% → 15% (2020-07-01). | I10: FATOORA e-invoices + declared return boxes; also needs Counterparty BP-master | J10: R07 | K10: Inconsistent tax-category coding | L10: category | M10: mistake | N10: Medium | O10: Yes → Government_Supplied_Sales | P10: Out of scope | Q10: Needs a feed the PoC does not have: Counterparty BP-master. | R10: No | S10: Yes
A11: 7 | B11: OUT-07 | C11: Output | D11: Tax-point / period-straddle timing | E11: Assigns a sale to the wrong period — invoice date used when delivery/payment set an earlier tax point (or vice-versa) — so output lands in the adjacent period. | F11: `ACCOUNTING_METHODE` (cash vs accrual) applied inconsistently; `IssueDate` used as a proxy when `ActualDeliveryDate` or prepayment (386) triggered the tax point; quarter-end straddle. | G11: For invoices where `IssueDate` and `ActualDeliveryDate` fall in different return periods, recompute the correct period (goods = delivery; prepayment 386 = payment; per `ACCOUNTING_METHODE`). Flag invoices whose declared period ≠ correct period; quantify per-period over/under-declaration. | H11: VAT Mistakes Rulebook (docs/VAT-Mistakes-Rulebook.md), family Output — authored for this PoC. No explicit statutory citation recorded in the repo — to be confirmed with a ZATCA SME. | I11: FATOORA e-invoices + declared return boxes; also needs AP / payment ledger | J11: T02 | K11: Invoice issued before the tax point | L11: tax-point | M11: explanation | N11: Medium | O11: Yes → Standard_Rate_Sales (timing) | P11: In scope — wired | Q11: Draws a live bridge line (app/reconciling_items.py). | R11: Yes | S11: Yes
A12: 8 | B12: OUT-08 | C12: Output | D12: Output VAT not charged on deemed/nominal supplies | E12: No output VAT on deemed supplies — free samples/gifts above de-minimis, business assets to private use, or assets on hand at deregistration — because no ordinary sales invoice is raised. | F12: "No money received = no VAT"; deregistration wind-down overlooked; give-aways not treated as supplies. | G12: Weak-signal, cross-source: (a) at deregistration (`DEREG_TYPE` set, `TO_DATE` in period) expect deemed-supply output on closing assets — often absent; (b) reconcile large `AllowanceTotalAmount`/zero-value/100%-discount lines carrying no `TaxAmount`; (c) `IND_SECTOR` give-away norm. Flag deregistration or material zero-consideration outputs with **no** corresponding output VAT. | H12: VAT Mistakes Rulebook (docs/VAT-Mistakes-Rulebook.md), family Output — authored for this PoC. No explicit statutory citation recorded in the repo — to be confirmed with a ZATCA SME. | I12: FATOORA e-invoices + declared return boxes; also needs Registration / dereg master | J12: S09 | K12: Deemed supply | L12: population | M12: mistake | N12: Medium | O12: No (compliance/valuation) | P12: Out of scope | Q12: Needs a feed the PoC does not have: Registration / dereg master. | R12: No | S12: Yes
A13: 9 | B13: OUT-09 | C13: Output | D13: Excessive / fictitious credit notes suppressing output | E13: Over-uses credit notes (`381`) to reduce declared output — without a genuine return/cancellation, or in the wrong period — so net Standard_Rate_Sales is understated. | F13: Managing declared VAT down at period-end; genuine adjustment in the wrong period; credit note issued but the supply still stands. | G13: Credit-note ratio = Σ `TaxAmount`[381] ÷ Σ `TaxAmount`[388] per period; flag vs `IND_SECTOR`/`BUSINESS_SIZE` peer norm or a period-on-period spike. Verify each material 381 references a valid original 388 (matching buyer, ≤ original, in-period tax point). Unmatched/over-value credit notes are added back: understated output = Σ invalid 381 `TaxAmount`. **Scope split vs COR-01:** OUT-09 = *invalid/excess* credits (added back); COR-01 = *valid* credits *not netted* (over-declaration). One 381 belongs to exactly one path. | H13: VAT Mistakes Rulebook (docs/VAT-Mistakes-Rulebook.md), family Output — authored for this PoC. No explicit statutory citation recorded in the repo — to be confirmed with a ZATCA SME. | I13: FATOORA e-invoices + declared VAT return boxes (in the PoC data model) | J13: R04 | K13: Unusually high credit-note ratio | L13: adjustment | M13: mistake | N13: High | O13: Yes → Standard_Rate_Sales (netting) | P13: In scope — not wired | Q13: Reachable from the PoC's data model; no reconciling item written yet. | R13: No | S13: Yes
A14: 10 | B14: OUT-10 | C14: Output | D14: Supplies to connected persons below fair market value | E14: Supplies to related parties (where the recipient can't fully recover) priced below open-market value, understating output — VAT is due on FMV. | F14: Intercompany pricing set for non-VAT reasons; unaware of the FMV override. | G14: Identify connected-party invoices (shared ownership, `VAT_GROUP_REP_FLAG` relationships, repeated counterparty) whose unit price is materially below the taxpayer's arm's-length norm for the same item; uplift = (FMV − charged) × 15%. | H14: VAT Mistakes Rulebook (docs/VAT-Mistakes-Rulebook.md), family Output — authored for this PoC. No explicit statutory citation recorded in the repo — to be confirmed with a ZATCA SME. | I14: FATOORA e-invoices + declared return boxes; also needs Counterparty BP-master | J14: R10 | K14: Return inconsistent with the sector or historical profile | L14: category | M14: mistake | N14: Medium | O14: No (valuation) | P14: Out of scope | Q14: Needs a feed the PoC does not have: Counterparty BP-master. | R14: No | S14: Yes
A15: 11 | B15: INP-01 | C15: Input | D15: Input VAT claimed with no valid cleared tax invoice | E15: Claims input VAT it holds no cleared 388 for — estimates, pro-forma, statements, or docs never cleared on FATOORA. | F15: Honest timing (invoice not yet cleared) or evasion (inflating recoverable VAT with no document). | G15: Declared `Standard_Rate_Purchase_VAT_Amount (+_Adjustment)` vs recoverable-input pool. Flag residual where declared − pool > τ. The portion with **no matching cleared 388 where taxpayer = buyer** (`STATUSCODE`≠cleared / `CLEANCEENABLED` false / no invoice) is the exposure. | H15: VAT Mistakes Rulebook (docs/VAT-Mistakes-Rulebook.md), family Input — authored for this PoC. No explicit statutory citation recorded in the repo — to be confirmed with a ZATCA SME. | I15: FATOORA e-invoices + declared return boxes; also needs Registration / dereg master | J15: R08 | K15: Buyer–supplier mismatch | L15: status | M15: mistake | N15: High | O15: Yes → Standard_Rate_Purchase_VAT | P15: Out of scope | Q15: Needs a feed the PoC does not have: Registration / dereg master. | R15: No | S15: Yes
A16: 12 | B16: INP-02 | C16: Input | D16: Input VAT on blocked / non-deductible items | E16: Recovers VAT on restricted costs — entertainment, catering/hospitality, employee private use, passenger vehicles not wholly for business. | F16: Misunderstanding KSA blocking rules; treats all supplier VAT as recoverable. | G16: Screen purchase lines for restricted categories via **supplier** sector (restaurants, hotels, catering, car dealers/rental) plus `INVOICELINE` descriptions. Sum VAT on flagged lines; any included in `Standard_Rate_Purchase_VAT_Amount` is disallowed. | H16: VAT Mistakes Rulebook (docs/VAT-Mistakes-Rulebook.md), family Input — authored for this PoC. No explicit statutory citation recorded in the repo — to be confirmed with a ZATCA SME. | I16: FATOORA e-invoices + declared return boxes; also needs Counterparty BP-master | J16: A02 | K16: Partial input-tax recovery | L16: category | M16: mistake | N16: Medium (High fleet/entertainment) | O16: Yes → Standard_Rate_Purchase_VAT | P16: Out of scope | Q16: Needs a feed the PoC does not have: Counterparty BP-master. | R16: No | S16: Yes
... A69: 65 | B69: DAT-12 | C69: Data | D69: Manual portal data-entry / internal-consistency errors | E69: Hand-typing the return introduces transpositions, decimal shifts, or misfooted totals — `Amount × rate ≠ VAT_Amount`, subtotals that don't add, or a wrong net line. | F69: Manual keying with no e-invoice import; fat-finger and copy-paste errors. | G69: Deterministic self-checks needing no e-invoice data: (a) each rated box `Amount × 0.15` (or `× 0.05` for `_5`) ≈ `VAT_Amount` — ratios near 0.015/1.5/0.05× flag a decimal shift/transposition; (b) `Total_VAT_Due` (Box13) = Σ output VAT boxes; (c) `Net_Due_VAT`/`Final_VAT_Due` (Box16) = `Total_VAT_Due` (Box13) + `Corrections_From_Previous_Period` (Box14) − `VAT_Credit` (Box15), **with the Box14 sign taken from the shared `box14_sign_mode`** (not hard-coded); (d) recompute `Standard_Rate_Purchase_VAT_Amount`; each failing beyond τ. | H69: VAT Mistakes Rulebook (docs/VAT-Mistakes-Rulebook.md), family Data — authored for this PoC. No explicit statutory citation recorded in the repo — to be confirmed with a ZATCA SME. | I69: FATOORA e-invoices + declared VAT return boxes (in the PoC data model) | J69: A09 | K69: Unallocated accounting adjustment | L69: materiality | M69: risk | N69: Medium (High on totals) | O69: No (arithmetic pre-gate) | P69: In scope — not wired | Q69: Reachable from the PoC's data model; no reconciling item written yet. | R69: No | S69: Yes

Sheet Categories
A1: Rule categories and the taxonomy dimensions
A2: Rule counts are live COUNTIF formulas against the Rules sheet, so they stay correct if rules are added or reclassified.
A4: A. Rule families — the six categories in the 'Category' column
A5: Family | B5: Code prefix | C5: What it covers | D5: Rules | E5: Wired | F5: In scope | G5: Out of scope
A6: Output | B6: OUT | C6: Where the declared output position diverges from output VAT reconstructed from sales-direction invoice lines — omissions, wrong rate, wrong box, tax-point timing, suppressed sales. | D6: =COUNTIF(Rules!$C$5:$C$69,$A6) -> 10 | E6: =COUNTIFS(Rules!$C$5:$C$69,$A6,Rules!$R$5:$R$69,"Yes") -> 1 | F6: =COUNTIFS(Rules!$C$5:$C$69,$A6,Rules!$P$5:$P$69,"In scope*") -> 5 | G6: =COUNTIFS(Rules!$C$5:$C$69,$A6,Rules!$P$5:$P$69,"Out of scope") -> 5
A7: Input | B7: INP | C7: Where the input-VAT claim is not supported by valid purchase evidence — no cleared invoice, blocked or non-deductible items, no apportionment, duplicate or wrong-period claims. | D7: =COUNTIF(Rules!$C$5:$C$69,$A7) -> 11 | E7: =COUNTIFS(Rules!$C$5:$C$69,$A7,Rules!$R$5:$R$69,"Yes") -> 1 | F7: =COUNTIFS(Rules!$C$5:$C$69,$A7,Rules!$P$5:$P$69,"In scope*") -> 3 | G7: =COUNTIFS(Rules!$C$5:$C$69,$A7,Rules!$P$5:$P$69,"Out of scope") -> 8
A8: Reverse-charge | B8: RCM | C8: Imports and reverse charge: the populations that carry no domestic e-invoice, so they can only be proven from customs and AP feeds. | D8: =COUNTIF(Rules!$C$5:$C$69,$A8) -> 10 | E8: =COUNTIFS(Rules!$C$5:$C$69,$A8,Rules!$R$5:$R$69,"Yes") -> 0 | F8: =COUNTIFS(Rules!$C$5:$C$69,$A8,Rules!$P$5:$P$69,"In scope*") -> 0 | G8: =COUNTIFS(Rules!$C$5:$C$69,$A8,Rules!$P$5:$P$69,"Out of scope") -> 10
A9: Corrections | B9: COR | C9: Credit and debit notes, bad-debt relief, self-corrections, return versioning and amendments — anything that restates an earlier position. | D9: =COUNTIF(Rules!$C$5:$C$69,$A9) -> 10 | E9: =COUNTIFS(Rules!$C$5:$C$69,$A9,Rules!$R$5:$R$69,"Yes") -> 2 | F9: =COUNTIFS(Rules!$C$5:$C$69,$A9,Rules!$P$5:$P$69,"In scope*") -> 4 | G9: =COUNTIFS(Rules!$C$5:$C$69,$A9,Rules!$P$5:$P$69,"Out of scope") -> 6
A10: Compliance | B10: CMP | C10: Filing and registration behaviour: late filing or payment, registration and deregistration, group changes, filing frequency, mandate waves. | D10: =COUNTIF(Rules!$C$5:$C$69,$A10) -> 12 | E10: =COUNTIFS(Rules!$C$5:$C$69,$A10,Rules!$R$5:$R$69,"Yes") -> 0 | F10: =COUNTIFS(Rules!$C$5:$C$69,$A10,Rules!$P$5:$P$69,"In scope*") -> 5 | G10: =COUNTIFS(Rules!$C$5:$C$69,$A10,Rules!$P$5:$P$69,"Out of scope") -> 7
A11: Data | B11: DAT | C11: E-invoicing data integrity: completeness both ways, late clearance, rejected and duplicate documents, wrong party or direction, currency and rounding. | D11: =COUNTIF(Rules!$C$5:$C$69,$A11) -> 12 | E11: =COUNTIFS(Rules!$C$5:$C$69,$A11,Rules!$R$5:$R$69,"Yes") -> 0 | F11: =COUNTIFS(Rules!$C$5:$C$69,$A11,Rules!$P$5:$P$69,"In scope*") -> 5 | G11: =COUNTIFS(Rules!$C$5:$C$69,$A11,Rules!$P$5:$P$69,"Out of scope") -> 7
A12: Total | D12: =SUM(D6:D11) -> 65 | E12: =SUM(E6:E11) -> 4 | F12: =SUM(F6:F11) -> 22 | G12: =SUM(G6:G11) -> 43
A14: B. Rule kinds — what sort of object a rule is (drives what the engine does with it)
A15: Kind | B15: Meaning | C15: What the engine does with it | D15: Rules
A16: explanation | B16: A legitimate reason the return differs from the e-invoices — credit notes, tax-point timing, transmission lag. | C16: Becomes a bridge line and reduces the unexplained residual. | D16: =COUNTIF(Rules!$M$5:$M$69,$A16) -> 5
A17: mistake | B17: A taxpayer error. | C17: Becomes a finding, quantified against the residual. | D17: =COUNTIF(Rules!$M$5:$M$69,$A17) -> 48
A18: risk | B18: A behavioural or data-quality signal — late filing, rounding drift, broken continuity. | C18: Feeds case prioritisation only. It must never draw a bridge line. | D18: =COUNTIF(Rules!$M$5:$M$69,$A18) -> 12
A20: C. Reason-code groups — which class of difference a rule is about
A21: Group | B21: Codes | C21: What it describes | D21: Rules
A22: timing | B22: T01–T08 (8 codes) | C22: The return and the invoice sit in different periods — tax point, transmission lag, cash basis, advance payments, prior-period corrections. | D22: =COUNTIF(Rules!$J$5:$J$69,"T*") -> 6
A23: scope | B23: S01–S09 (9 codes) | C23: Populations that carry no domestic e-invoice at all — imports, reverse charge, exempt, outside-scope, VAT-group internal, deemed supplies. | D23: =COUNTIF(Rules!$J$5:$J$69,"S*") -> 15
A24: document | B24: D01–D08 (8 codes) | C24: Document structure — credit and debit notes, replacements, rejections, duplicates, B2C aggregation, summary invoices. | D24: =COUNTIF(Rules!$J$5:$J$69,"D*") -> 8
A25: accounting | B25: A01–A09 (9 codes) | C25: Accounting and tax treatment — deduction timing, partial recovery, bad debts, amendments, rounding, currency. | D25: =COUNTIF(Rules!$J$5:$J$69,"A*") -> 14
A26: risk | B26: R01–R10 (10 codes) | C26: Behavioural indicators that rank a case rather than explain a number. | D26: =COUNTIF(Rules!$J$5:$J$69,"R*") -> 22
A28: D. Evaluation stages — the precedence a difference is tested against
A29: # | B29: Stage | C29: The question it answers | D29: Rules
A30: 1 | B30: population | C30: Is a Saudi e-invoice expected for this transaction at all? | D30: =COUNTIF(Rules!$L$5:$L$69,$B30) -> 7
A31: 2 | B31: identity | C31: Does it belong to this taxpayer, branch or tax group? | D31: =COUNTIF(Rules!$L$5:$L$69,$B31) -> 9
A32: 3 | B32: status | C32: Is the document valid, cleared, rejected, cancelled or duplicated? | D32: =COUNTIF(Rules!$L$5:$L$69,$B32) -> 4
A33: 4 | B33: tax-point | C33: Which date determines the VAT period? | D33: =COUNTIF(Rules!$L$5:$L$69,$B33) -> 3
A34: 5 | B34: category | C34: Standard, zero-rated, exempt, reverse charge or outside scope? | D34: =COUNTIF(Rules!$L$5:$L$69,$B34) -> 18
A35: 6 | B35: adjustment | C35: Is it a credit note, debit note, bad debt or correction? | D35: =COUNTIF(Rules!$L$5:$L$69,$B35) -> 12
A36: 7 | B36: aggregation | C36: Individual invoice, summary invoice or B2C batch? | D36: =COUNTIF(Rules!$L$5:$L$69,$B36) -> 1
A37: 8 | B37: timing | C37: Is the difference inside an acceptable reporting window? | D37: =COUNTIF(Rules!$L$5:$L$69,$B37) -> 2
A38: 9 | B38: materiality | C38: Is the residual above the taxpayer-specific tolerance? | D38: =COUNTIF(Rules!$L$5:$L$69,$B38) -> 6
A39: 10 | B39: risk | C39: Is it persistent, unusual, or corroborated by other signals? | D39: =COUNTIF(Rules!$L$5:$L$69,$B39) -> 3
A41: Only after every stage above has failed to explain a residual may it be called potentially non-compliant.

Sheet Prioritisation
A1: Case prioritisation — how the queue is ordered
A2: Composite score from four normalised signals (app/priority.py). The worked example recalculates from the weights, so changing a weight re-ranks the queue.
A4: A. The four signals
A5: Signal | B5: Weight | C5: What it measures | D5: How it is computed | E5: Normalisation
A6: Exposure | B6: 0.4 | C6: How much revenue is at stake on this case. | D6: Output residual (absolute) plus any input-VAT over-claim — combined.priority_exposure. | E6: Divided by a SAR 100,000 ceiling, capped at 1.0.
A7: Deadline | B7: 0.3 | C7: How close the audit SLA is. | D7: Days between today and the case's sla_due date. | E7: Ramped across a 90-day window: 1 − days/90, clamped to 0–1. Past due scores 1.0.
A8: History | B8: 0.2 | C8: Whether this taxpayer has previous findings. | D8: Prior closed cases with a tax difference, plus amended returns on file. | E8: 0.5 per prior finding + 0.25 per amended return, capped at 1.0.
A9: Quick win | B9: 0.1 | C9: How little work is left to close the case. | D9: The share of the apparent gap the bridge already explains (explained_pct). | E9: Already a 0–1 fraction.
A10: Total | B10: =SUM(B6:B9) -> 1
A12: B. Score bands
A13: Band | B13: Score | C13: What it means for the auditor
A14: High | B14: 60 – 100 | C14: Work it now — material exposure, or the SLA is close, or both.
A15: Medium | B15: 35 – 59 | C15: Schedule it. Real but not urgent.
A16: Low | B16: 0 – 34 | C16: Park it. Small exposure and a comfortable deadline.
A18: C. Constants
A19: Constant | B19: Value | C19: Effect
A20: Exposure ceiling | B20: 100000 | C20: The residual that scores a full 1.0 on exposure.
A21: SLA window (days) | B21: 90 | C21: The window across which deadline urgency ramps from 0 to 1.
A22: Materiality floor (SAR) | B22: 1000 | C22: Residual below this is never a finding.
A23: Materiality rate | B23: 0.005 | C23: Or 0.5% of the compared box, whichever is larger.
A25: D. Worked example — the six open demo cases
A26: Case | B26: Taxpayer | C26: Exposure signal | D26: Deadline signal | E26: History signal | F26: Quick-win signal | G26: Score | H26: Band
A27: CASE-2025-0481 | B27: Al-Faisaliah Trading Co. | C27: 0.75 | D27: 0.867 | E27: 0.5 | F27: 0.844 | G27: =ROUND((($B$6*C27)+($B$7*D27)+($B$8*E27)+($B$9*F27))*100,0) -> 74 | H27: =IF(G27>=60,"High",IF(G27>=35,"Medium","Low")) -> High
A28: CASE-2025-0485 | B28: Najd Electronics Trading | C28: 1 | D28: 0.722 | E28: 0 | F28: 0.083 | G28: =ROUND((($B$6*C28)+($B$7*D28)+($B$8*E28)+($B$9*F28))*100,0) -> 62 | H28: =IF(G28>=60,"High",IF(G28>=35,"Medium","Low")) -> High
A29: CASE-2025-0486 | B29: Yanbu Petrochem Supplies | C29: 1 | D29: 0.556 | E29: 0 | F29: 0 | G29: =ROUND((($B$6*C29)+($B$7*D29)+($B$8*E29)+($B$9*F29))*100,0) -> 57 | H29: =IF(G29>=60,"High",IF(G29>=35,"Medium","Low")) -> Medium
A30: CASE-2025-0483 | B30: Rawabi Construction Co. | C30: 0 | D30: 0.667 | E30: 0 | F30: 1 | G30: =ROUND((($B$6*C30)+($B$7*D30)+($B$8*E30)+($B$9*F30))*100,0) -> 30 | H30: =IF(G30>=60,"High",IF(G30>=35,"Medium","Low")) -> Low
A31: CASE-2025-0484 | B31: Tabuk Logistics Co. | C31: 0 | D31: 0.444 | E31: 0 | F31: 1 | G31: =ROUND((($B$6*C31)+($B$7*D31)+($B$8*E31)+($B$9*F31))*100,0) -> 23 | H31: =IF(G31>=60,"High",IF(G31>=35,"Medium","Low")) -> Low
A32: CASE-2025-0482 | B32: Nael Foodstuff Est. | C32: 0 | D32: 0.5 | E32: 0 | F32: 0 | G32: =ROUND((($B$6*C32)+($B$7*D32)+($B$8*E32)+($B$9*F32))*100,0) -> 15 | H32: =IF(G32>=60,"High",IF(G32>=35,"Medium","Low")) -> Low
A34: Signal values (blue) are the engine's output for the seeded demo data on 2026-08-15; Score and Band are formulas over the weights in block A. Deadline signals move as the SLA date approaches.

Sheet Data Model
A1: Data model — tables, structure and joins
A2: Two PostgreSQL schemas. 'core' holds what the taxpayer declared and what the e-invoices evidence; 'recon' holds the reconciliation working state the engine writes. Row counts are the seeded demo volumes.
A4: A. Tables
A5: Schema.table | B5: Purpose | C5: Rows in the demo
A6: core.taxpayer | B6: The audited business: VAT number, sector, size, accounting basis, residency, registration dates. | C6: 6
A7: core.vat_return | B7: One filed return per taxpayer per period, with version and current flag, submission and deadline dates, and the Box 13–16 totals. | C7: 6
A8: core.vat_return_box | B8: The declared position, normalised one row per box: base, VAT and the taxpayer's own adjustment. | C8: 14
A9: core.invoice | B9: A cleared or reported FATOORA e-invoice — the evidence population. Direction says whether the taxpayer is seller or buyer. | C9: 156
A10: core.invoice_taxsubtotal | B10: The linchpin: taxable base and VAT per tax category × rate. Aggregating this is what rebuilds the return. | C10: 156
A11: core.audit_case | B11: A case referred by the upstream risk engine, plus closed-case outcome labels used for the history signal. | C11: 7
A12: core.rule_library | B12: The rulebook as data — 65 rules with taxonomy, severity and enabled flag. | C12: 65
A13: core.assumptions | B13: Flippable modelling assumptions (tax point, version selector, materiality). | C13: 6
A14: core.code_dictionary | B14: Decode lists: invoice types, tax categories, case reasons, and the 44 difference reason codes. | C14: 54
A15: recon.case_recon | B15: One reconciliation run per case: declared, rebuilt, gap, explained, residual. | C15: written at runtime
A16: recon.rebuilt_box | B16: The reconstructed box beside the declared one. | C16: written at runtime
A17: recon.bridge_line | B17: One row per bridge line, carrying the rule code that authorised it. | C17: written at runtime
A18: recon.residual | B18: The unexplained remainder with its materiality band and state. | C18: written at runtime
A19: recon.conclusion | B19: The case verdict and financial impact, plus the AI-drafted narrative. | C19: written at runtime
A20: recon.event_log | B20: Append-only action log (production: hash-chained). | C20: written at runtime
A21: recon.taxpayer_response | B21: Evidence the taxpayer supplied; the auditor confirms the SAR amount, and the engine folds it in as a RESP-xx bridge line. | C21: written at runtime
A23: B. Table structure (the tables the engine reads and writes on every run)
A24: Schema.table | B24: Column | C24: Type / key | D24: Notes
A25: core.taxpayer | B25: id | C25: int PK | D25: Surrogate key.
B26: vat_registration_number | C26: varchar(20) UNIQUE | D26: The 15-digit VAT number — the real-world identity.
B27: partner, id_number | C27: varchar(20) | D27: Business-partner and national/commercial ID.
B28: name | C28: varchar(200) | D28: Legal name. Pseudonymised before any model call.
B29: ind_sector | C29: varchar(80) | D29: Sector, used for peer comparison.
B30: business_size | C30: varchar(20) | D30: micro / small / medium / large.
B31: accounting_method | C31: varchar(20) | D31: accrual / cash — decides whether payment date moves the tax point.
B32: resident_flag | C32: bool | D32: Residency.
B33: vat_group_rep_flag | C33: bool | D33: True if this is a VAT-group representative.
B34: bp_type | C34: varchar(20) | D34: org / individual.
B35: reg_from, reg_to, dereg_type | C35: date / varchar | D35: Registration window and deregistration reason.
A36: core.vat_return | B36: id | C36: int PK | D36: Surrogate key.
B37: form_number | C37: varchar(30) | D37: The filing reference.
B38: taxpayer_id | C38: int FK → core.taxpayer.id | D38: Owner of the return.
B39: period_from, period_to | C39: date | D39: The tax period. Joined to the case's period.
B40: data_version | C40: int | D40: 1 = original, higher = amendment.
B41: current_flag | C41: bool | D41: Marks the version currently in force.
B42: reason_for_amendment | C42: varchar(200) | D42: Free text — read by the AI layer, never by the engine.
...
